Workbook

Sheet README
B1: Scribl D2C - Infrastructure TCO Model
B3: What this is
B4: A 30-month run-rate model (Oct 2026 - Mar 2029) for Scribl D2C infrastructure, built bottom-up from the six
B5: consumption pillars: Compute (EKS), Security (Cognito + WAF), Networking (ALB + data transfer),
B6: Database (DynamoDB + Aurora), Storage (S3), and AI App (Bedrock + Claude). A Data Lake / ML research
B7: workstream switches on after Year 1 for mental-health outcomes research and dataset publishing. Unit prices
B8: are anchored to AWS us-east-2 (Ohio) and Anthropic rates, both validated June 2026.
B10: Drivers of consumption
B11: Pillars are listed largest first. AI Inference is the dominant line, around 60% of the 30-month total and
B12: about two-thirds at full scale. The rest is real infrastructure: the model runs three environments (dev,
B13: stage, prod), so compute and database carry an always-on baseline. The gross floor is around $11k/month at
B14: launch; roughly $9.5k is demand-driven and the remainder is reserved launch-readiness headroom you can dial
... B20: headline, and a moderation check on every submission. The calls Claude makes inside the product:
B21: Inference feature | C21: Model | D21: Fires on | E21: Calls/mo @ 5M | F21: Share of AI $
B22: Daily prompt generation | C22: Opus 4.8 | D22: Once per day, all users | E22: ~150 | F22: <0.1%
B23: Drawing read + caption/headline | C23: Sonnet 4.6 (vision) | D23: Every drawing submitted | E23: ~14.6M | F23: ~78%
B24: Content moderation | C24: Haiku 4.5 | D24: Every submission | E24: ~26.6M | F24: ~22%
B25: Personalized follow-ups | C25: Agentic (memory) | D25: Post-launch; not modelled | E25: -- | F25: --
B26: Exciting Artifact composition | C26: Generative | D26: Q1 2027; not modelled | E26: -- | F26: --
B27: Shares are at default assumptions and 5M users. The two post-launch features are listed for completeness;
B28: neither is in the cost numbers.
B30: Compute (EKS)
B31: One EKS cluster per environment runs the application services. Production runs in every active region while
B32: dev and stage stay in the primary region, so the cluster count goes from three today (dev, stage, prod in
B33: Ohio) to five at full three-region expansion (prod in all three regions, plus dev and stage in Ohio). The
B34: Drivers tab shows this count, and control plane, load balancers, NAT, and WAF all scale with it. Production
B35: worker nodes scale with DAU from a four-node HA floor (m5.xlarge, us-east-2, 25% Savings Plan), with dev and
B36: stage at half. Observability (CloudWatch, Prometheus, Grafana, X-Ray) has a fixed base per environment plus a variable component
B37: that grows with API traffic. The platform baseline (ECR, Secrets, CI, bastion) stays fixed. An explicit
B38: reserved/standby line sets how much launch-readiness and DR headroom you hold ahead of demand.
B40: Security (Cognito + WAF)
... B76: Assumptions tab.
B77: Region | C77: Role | D77: Live from | E77: Premium vs Ohio
B78: us-east-2 (Ohio) | C78: Primary | D78: Month 1 (launch) | E78: baseline
B79: eu-west-2 (London) | C79: European expansion | D79: Year 2 (month 13) | E79: ~8%
B80: ap-southeast-1 (Singapore) | C80: Asian market | D80: Year 2.5 (month 25) | E80: ~18%
B81: Premiums follow AWS regional pricing: London a few points above Ohio, Asia Pacific roughly 20-30% on compute
B82: and higher on egress. Only the share of traffic in a region carries its premium, so the blended effect on
B83: total cost is a few percent, not the headline premium. The research data lake stays in Ohio and is not
B84: uplifted.

Sheet Summary
B1: Scribl D2C - 2.5-Year Infrastructure TCO
B2: List-price cost, no partner discounts. Two views: monthly run rate (how cost scales) and cumulative spend (what you budget).
B4: Monthly run rate by pillar ($/mo) | C4: Year 1 avg/mo | D4: Year 2 avg/mo | E4: Yr3 H1 avg/mo | F4: At scale (M30)
B5: Compute (EKS) | C5: =SUM(Costs!C11:N11)/12 -> 5011.7565 | D5: =SUM(Costs!O11:Z11)/12 -> 8046.299 | E5: =SUM(Costs!AA11:AF11)/6 -> 10529.314 | F5: =Costs!AF11 -> 11080.427
B6: Security (Cognito, WAF) | C6: =SUM(Costs!C15:N15)/12 -> 560.7425 | D6: =SUM(Costs!O15:Z15)/12 -> 5924.4147 | E6: =SUM(Costs!AA15:AF15)/6 -> 9209.5095 | F6: =Costs!AF15 -> 9970.5
B7: Networking (ALB, transfer) | C7: =SUM(Costs!C21:N21)/12 -> 981.09226 | D7: =SUM(Costs!O21:Z21)/12 -> 7563.4797 | E7: =SUM(Costs!AA21:AF21)/6 -> 12674.022 | F7: =Costs!AF21 -> 13844.528
B8: Database (DynamoDB, Aurora) | C8: =SUM(Costs!C30:N30)/12 -> 3712.3675 | D8: =SUM(Costs!O30:Z30)/12 -> 5877.3644 | E8: =SUM(Costs!AA30:AF30)/6 -> 8046.0653 | F8: =Costs!AF30 -> 8552.546
B9: Storage (S3) | C9: =SUM(Costs!C34:N34)/12 -> 49.936856 | D9: =SUM(Costs!O34:Z34)/12 -> 797.25375 | E9: =SUM(Costs!AA34:AF34)/6 -> 1983.8927 | F9: =Costs!AF34 -> 2375.1668
B10: AI App (Bedrock + Claude) | C10: =SUM(Costs!C39:N39)/12 -> 7118.3263 | D10: =SUM(Costs!O39:Z39)/12 -> 72943.961 | E10: =SUM(Costs!AA39:AF39)/6 -> 120738.95 | F10: =Costs!AF39 -> 132340.32
B11: Data Lake / ML research | C11: =SUM(Costs!C47:N47)/12 -> 0 | D11: =SUM(Costs!O47:Z47)/12 -> 2090.5954 | E11: =SUM(Costs!AA47:AF47)/6 -> 3810.3495 | F11: =Costs!AF47 -> 4470
B12: Total run rate ($/mo) | C12: =SUM(C5:C11) -> 17434.222 | D12: =SUM(D5:D11) -> 103243.37 | E12: =SUM(E5:E11) -> 166992.1 | F12: =SUM(F5:F11) -> 182633.49
B14: Cumulative spend ($) | C14: Year 1 (12 mo) | D14: Year 2 (12 mo) | E14: Yr3 H1 (6 mo) | F14: 30-mo total
B15: Total cost (TCO) | C15: =SUM(Costs!C49:N49) -> 209210.66 | D15: =SUM(Costs!O49:Z49) -> 1238920.4 | E15: =SUM(Costs!AA49:AF49) -> 1001952.6 | F15: =SUM(C15:E15) -> 2450083.7
B17: Unit economics
B18: Registered users at period end | C18: =Drivers!N7 -> 1000000 | D18: =Drivers!Z7 -> 3900000 | E18: =Drivers!AF7 -> 5000000 | F18: =Drivers!AF7 -> 5000000
B19: Cost per registered user (period) | C19: =C15/C18 -> 0.20921066 | D19: =D15/D18 -> 0.3176719 | E19: =E15/E18 -> 0.20039053 | F19: =F15/F18 -> 0.49001674
B20: Submissions in period | C20: =SUM(Drivers!C11:N11) -> 17157000 | D20: =SUM(Drivers!O11:Z11) -> 175932400 | E20: =SUM(Drivers!AA11:AF11) -> 145608400 | F20: =SUM(C20:E20) -> 338697800
B21: Cost per submission | C21: =C15/C20 -> 0.012193895 | D21: =D15/D20 -> 0.0070420253 | E21: =E15/E20 -> 0.0068811458 | F21: =F15/F20 -> 0.0072338341
B23: Headline
B24: 30-month TCO | C24: =F15 -> 2450083.7
B25: AI App as % of TCO | C25: =SUM(Costs!C39:AF39)/F15 -> 0.68780554
B26: Run rate at launch (M1) / at scale (M30) | C26: =Costs!C49 -> 9107.3487 | D26: =Costs!AF49 -> 182633.49

Sheet Assumptions
B1: Scribl D2C | Infrastructure TCO | Assumptions
B2: All blue cells are editable inputs. Every cost on the Costs tab is driven from here. 30-month horizon (Oct 2026 - Mar 2029).
B4: Engagement
B5: DAU as % of registered users | C5: 0.25 | D5: Mature daily-habit apps run 20-30%. Largest single swing factor.
B6: MAU as % of registered users | C6: 0.45 | D6: Drives Cognito monthly-active billing.
B7: Prompt completion rate (of DAU) | C7: 0.7 | D7: PRFAQ target >=70%. Each completion = 1 submission + AI calls.
B8: Environments (dev, stage, prod)
B9: Number of environments | C9: 3 | D9: dev, stage, prod. Baselines apply to all; only prod scales with users.
B10: Non-prod size vs prod baseline | C10: 0.5 | D10: Each non-prod env at this fraction of prod's baseline.
B11: Submission mix (should sum to 100%)
B12: Drawing share of submissions | C12: 0.55 | D12: Only drawings trigger the Sonnet vision response.
B13: Text share of submissions | C13: 0.35
B14: Voice share of submissions | C14: 0.1 | D14: Voice transcribed on-device; no audio sent to Claude.
B15: Object sizes & media traffic
B16: Avg drawing object size (KB) | C16: 400 | D16: PNG from finger-on-glass canvas.
B17: Avg voice object size (KB) | C17: 500 | D17: ~30s clip.
B18: Avg text object size (KB) | C18: 5
B19: Avg served object size (KB) | C19: 320 | D19: Blended size streamed when viewing channels.
B20: Media views per DAU per day | C20: 18 | D20: Channel browsing after submit-to-unlock. Drives egress.
B21: Request volume
B22: API requests per DAU per day | C22: 60 | D22: Drives WAF + ALB request charges.
B23: S3 GET requests per DAU per day | C23: 25
B24: AI - token counts per call
B25: Moderation input tokens | C25: 1200 | D25: Haiku on every submission (text + image checks).
B26: Moderation output tokens | C26: 50
B27: Vision response input tokens | C27: 2500 | D27: Image (~1.6k) + prompt context. Sonnet, per drawing.
B28: Vision response output tokens | C28: 500
B29: Prompt-gen calls per day (universal) | C29: 5 | D29: ONE prompt for everyone + editorial A/B buffer. Opus.
B30: Prompt-gen input tokens | C30: 2000
B31: Prompt-gen output tokens | C31: 1000
B32: AI - Bedrock/Claude pricing ($ / million tokens)
B33: Haiku 4.5 input | C33: 1 | D33: Source: Anthropic pricing, Jun 2026.
B34: Haiku 4.5 output | C34: 5
B35: Sonnet 4.6 input | C35: 3
B36: Sonnet 4.6 output | C36: 15
B37: Opus 4.8 input | C37: 5
B38: Opus 4.8 output | C38: 25
B39: Prompt-caching discount on input | C39: 0.5 | D39: Applies to MODERATION only (real-time path); stable policy prompt cached. Image tokens are not cacheable.
B40: Batch discount on vision calls | C40: 0.5 | D40: Vision runs async (submit never blocks) -> Bedrock batch, 50% off. Batch path excludes prompt caching, so C39 does not apply to vision.
B41: Bedrock price adjustment vs API | C41: 0 | D41: Set if Bedrock token rates differ from first-party.
...

Sheet Drivers
B1: Volume Drivers
B2: Registered-user curve and research headcount are blue inputs; everything else is derived.
B4: Month # | C4: M1 | D4: M2 | E4: M3 | F4: M4 | G4: M5 | H4: M6 | I4: M7 | J4: M8 | K4: M9 | L4: M10 | M4: M11 | N4: M12 | O4: M13 | P4: M14 | Q4: M15 | R4: M16 | S4: M17 | T4: M18 | U4: M19 | V4: M20 | W4: M21 | X4: M22 | Y4: M23 | Z4: M24 | AA4: M25 | AB4: M26 | AC4: M27 | AD4: M28 | AE4: M29 | AF4: M30
B5: Calendar | C5: 46296 | D5: 46327 | E5: 46357 | F5: 46388 | G5: 46419 | H5: 46447 | I5: 46478 | J5: 46508 | K5: 46539 | L5: 46569 | M5: 46600 | N5: 46631 | O5: 46661 | P5: 46692 | Q5: 46722 | R5: 46753 | S5: 46784 | T5: 46813 | U5: 46844 | V5: 46874 | W5: 46905 | X5: 46935 | Y5: 46966 | Z5: 46997 | AA5: 47027 | AB5: 47058 | AC5: 47088 | AD5: 47119 | AE5: 47150 | AF5: 47178
B7: Registered users | C7: 8000 | D7: 18000 | E7: 32000 | F7: 52000 | G7: 75000 | H7: 100000 | I7: 150000 | J7: 230000 | K7: 340000 | L7: 500000 | M7: 720000 | N7: 1000000 | O7: 1200000 | P7: 1450000 | Q7: 1720000 | R7: 2050000 | S7: 2500000 | T7: 3000000 | U7: 3150000 | V7: 3300000 | W7: 3450000 | X7: 3600000 | Y7: 3750000 | Z7: 3900000 | AA7: 4100000 | AB7: 4300000 | AC7: 4500000 | AD7: 4650000 | AE7: 4820000 | AF7: 5000000
B8: Daily active users (DAU) | C8: =C7*Assumptions!$C$5 -> 2000 | D8: =D7*Assumptions!$C$5 -> 4500 | E8: =E7*Assumptions!$C$5 -> 8000 | F8: =F7*Assumptions!$C$5 -> 13000 | G8: =G7*Assumptions!$C$5 -> 18750 | H8: =H7*Assumptions!$C$5 -> 25000 | I8: =I7*Assumptions!$C$5 -> 37500 | J8: =J7*Assumptions!$C$5 -> 57500 | ... AF8: =AF7*Assumptions!$C$5 -> 1250000
B9: Monthly active users (MAU) | C9: =C7*Assumptions!$C$6 -> 3600 | D9: =D7*Assumptions!$C$6 -> 8100 | E9: =E7*Assumptions!$C$6 -> 14400 | F9: =F7*Assumptions!$C$6 -> 23400 | G9: =G7*Assumptions!$C$6 -> 33750 | H9: =H7*Assumptions!$C$6 -> 45000 | I9: =I7*Assumptions!$C$6 -> 67500 | J9: =J7*Assumptions!$C$6 -> 103500 | ... AF9: =AF7*Assumptions!$C$6 -> 2250000
B10: Submissions per day | C10: =C8*Assumptions!$C$7 -> 1400 | D10: =D8*Assumptions!$C$7 -> 3150 | E10: =E8*Assumptions!$C$7 -> 5600 | F10: =F8*Assumptions!$C$7 -> 9100 | G10: =G8*Assumptions!$C$7 -> 13125 | H10: =H8*Assumptions!$C$7 -> 17500 | I10: =I8*Assumptions!$C$7 -> 26250 | J10: =J8*Assumptions!$C$7 -> 40250 | ... AF10: =AF8*Assumptions!$C$7 -> 875000
B11: Submissions per month | C11: =C10*30.4 -> 42560 | D11: =D10*30.4 -> 95760 | E11: =E10*30.4 -> 170240 | F11: =F10*30.4 -> 276640 | G11: =G10*30.4 -> 399000 | H11: =H10*30.4 -> 532000 | I11: =I10*30.4 -> 798000 | J11: =J10*30.4 -> 1223600 | ... AF11: =AF10*30.4 -> 26600000
B12: Drawing submissions / mo | C12: =C11*Assumptions!$C$12 -> 23408 | D12: =D11*Assumptions!$C$12 -> 52668 | E12: =E11*Assumptions!$C$12 -> 93632 | F12: =F11*Assumptions!$C$12 -> 152152 | G12: =G11*Assumptions!$C$12 -> 219450 | H12: =H11*Assumptions!$C$12 -> 292600 | I12: =I11*Assumptions!$C$12 -> 438900 | J12: =J11*Assumptions!$C$12 -> 672980 | ... AF12: =AF11*Assumptions!$C$12 -> 14630000
B13: Text submissions / mo | C13: =C11*Assumptions!$C$13 -> 14896 | D13: =D11*Assumptions!$C$13 -> 33516 | E13: =E11*Assumptions!$C$13 -> 59584 | F13: =F11*Assumptions!$C$13 -> 96824 | G13: =G11*Assumptions!$C$13 -> 139650 | H13: =H11*Assumptions!$C$13 -> 186200 | I13: =I11*Assumptions!$C$13 -> 279300 | J13: =J11*Assumptions!$C$13 -> 428260 | ... AF13: =AF11*Assumptions!$C$13 -> 9310000
B14: Voice submissions / mo | C14: =C11*Assumptions!$C$14 -> 4256 | D14: =D11*Assumptions!$C$14 -> 9576 | E14: =E11*Assumptions!$C$14 -> 17024 | F14: =F11*Assumptions!$C$14 -> 27664 | G14: =G11*Assumptions!$C$14 -> 39900 | H14: =H11*Assumptions!$C$14 -> 53200 | I14: =I11*Assumptions!$C$14 -> 79800 | J14: =J11*Assumptions!$C$14 -> 122360 | ... AF14: =AF11*Assumptions!$C$14 -> 2660000
B15: Storage added (GB) | C15: =C12*Assumptions!$C$16/1048576+C13*Assumptions!$C$18/1048576+C14*Assumptions!$C$17/1048576 -> 11.029892 | D15: =D12*Assumptions!$C$16/1048576+D13*Assumptions!$C$18/1048576+D14*Assumptions!$C$17/1048576 -> 24.817257 | E15: =E12*Assumptions!$C$16/1048576+E13*Assumptions!$C$18/1048576+E14*Assumptions!$C$17/1048576 -> 44.119568 | F15: =F12*Assumptions!$C$16/1048576+F13*Assumptions!$C$18/1048576+F14*Assumptions!$C$17/1048576 -> 71.694298 | G15: =G12*Assumptions!$C$16/1048576+G13*Assumptions!$C$18/1048576+G14*Assumptions!$C$17/1048576 -> 103.40524 | H15: =H12*Assumptions!$C$16/1048576+H13*Assumptions!$C$18/1048576+H14*Assumptions!$C$17/1048576 -> 137.87365 | I15: =I12*Assumptions!$C$16/1048576+I13*Assumptions!$C$18/1048576+I14*Assumptions!$C$17/1048576 -> 206.81047 | J15: =J12*Assumptions!$C$16/1048576+J13*Assumptions!$C$18/1048576+J14*Assumptions!$C$17/1048576 -> 317.10939 | ... AF15: =AF12*Assumptions!$C$16/1048576+AF13*Assumptions!$C$18/1048576+AF14*Assumptions!$C$17/1048576 -> 6893.6825
B16: Storage cumulative (GB) | C16: =C15 -> 11.029892 | D16: =C16+D15 -> 35.847149 | E16: =D16+E15 -> 79.966717 | F16: =E16+F15 -> 151.66101 | G16: =F16+G15 -> 255.06625 | H16: =G16+H15 -> 392.9399 | I16: =H16+I15 -> 599.75038 | J16: =I16+J15 -> 916.85977 | K16: =J16+K15 -> 1385.6302 | ... AF16: =AE16+AF15 -> 87777.259
B17: Media egress (GB / mo) | C17: =C8*Assumptions!$C$20*Assumptions!$C$19/1048576*30.4 -> 333.98438 | D17: =D8*Assumptions!$C$20*Assumptions!$C$19/1048576*30.4 -> 751.46484 | E17: =E8*Assumptions!$C$20*Assumptions!$C$19/1048576*30.4 -> 1335.9375 | F17: =F8*Assumptions!$C$20*Assumptions!$C$19/1048576*30.4 -> 2170.8984 | G17: =G8*Assumptions!$C$20*Assumptions!$C$19/1048576*30.4 -> 3131.1035 | H17: =H8*Assumptions!$C$20*Assumptions!$C$19/1048576*30.4 -> 4174.8047 | I17: =I8*Assumptions!$C$20*Assumptions!$C$19/1048576*30.4 -> 6262.207 | J17: =J8*Assumptions!$C$20*Assumptions!$C$19/1048576*30.4 -> 9602.0508 | ... AF17: =AF8*Assumptions!$C$20*Assumptions!$C$19/1048576*30.4 -> 208740.23
B18: API requests (millions / mo) | C18: =C8*Assumptions!$C$22*30.4/1000000 -> 3.648 | D18: =D8*Assumptions!$C$22*30.4/1000000 -> 8.208 | E18: =E8*Assumptions!$C$22*30.4/1000000 -> 14.592 | F18: =F8*Assumptions!$C$22*30.4/1000000 -> 23.712 | G18: =G8*Assumptions!$C$22*30.4/1000000 -> 34.2 | H18: =H8*Assumptions!$C$22*30.4/1000000 -> 45.6 | I18: =I8*Assumptions!$C$22*30.4/1000000 -> 68.4 | J18: =J8*Assumptions!$C$22*30.4/1000000 -> 104.88 | ... AF18: =AF8*Assumptions!$C$22*30.4/1000000 -> 2280
B19: Research data scientists (FTE) | C19: 0 | D19: 0 | E19: 0 | F19: 0 | G19: 0 | H19: 0 | I19: 0 | J19: 0 | K19: 0 | L19: 0 | M19: 0 | N19: 0 | O19: 1 | P19: 1 | Q19: 2 | R19: 2 | S19: 2 | T19: 3 | U19: 3 | V19: 3 | W19: 4 | X19: 4 | Y19: 4 | Z19: 5 | AA19: 5 | AB19: 5 | AC19: 6 | AD19: 6 | AE19: 6 | AF19: 7
B20: Training GPU hours / mo | C20: =C19*Assumptions!$C$97 -> 0 | D20: =D19*Assumptions!$C$97 -> 0 | E20: =E19*Assumptions!$C$97 -> 0 | F20: =F19*Assumptions!$C$97 -> 0 | G20: =G19*Assumptions!$C$97 -> 0 | H20: =H19*Assumptions!$C$97 -> 0 | I20: =I19*Assumptions!$C$97 -> 0 | J20: =J19*Assumptions!$C$97 -> 0 | ... AF20: =AF19*Assumptions!$C$97 -> 840
B21: Active AWS regions | C21: =1+IF(1>=Assumptions!$C$100,1,0)+IF(1>=Assumptions!$C$101,1,0) -> 1 | D21: =1+IF(2>=Assumptions!$C$100,1,0)+IF(2>=Assumptions!$C$101,1,0) -> 1 | E21: =1+IF(3>=Assumptions!$C$100,1,0)+IF(3>=Assumptions!$C$101,1,0) -> 1 | F21: =1+IF(4>=Assumptions!$C$100,1,0)+IF(4>=Assumptions!$C$101,1,0) -> 1 | G21: =1+IF(5>=Assumptions!$C$100,1,0)+IF(5>=Assumptions!$C$101,1,0) -> 1 | H21: =1+IF(6>=Assumptions!$C$100,1,0)+IF(6>=Assumptions!$C$101,1,0) -> 1 | I21: =1+IF(7>=Assumptions!$C$100,1,0)+IF(7>=Assumptions!$C$101,1,0) -> 1 | J21: =1+IF(8>=Assumptions!$C$100,1,0)+IF(8>=Assumptions!$C$101,1,0) -> 1 | K21: =1+IF(9>=Assumptions!$C$100,1,0)+IF(9>=Assumptions!$C$101,1,0) -> 1 | L21: =1+IF(10>=Assumptions!$C$100,1,0)+IF(10>=Assumptions!$C$101,1,0) -> 1 | M21: =1+IF(11>=Assumptions!$C$100,1,0)+IF(11>=Assumptions!$C$101,1,0) -> 1 | N21: =1+IF(12>=Assumptions!$C$100,1,0)+IF(12>=Assumptions!$C$101,1,0) -> 1 | O21: =1+IF(13>=Assumptions!$C$100,1,0)+IF(13>=Assumptions!$C$101,1,0) -> 2 | P21: =1+IF(14>=Assumptions!$C$100,1,0)+IF(14>=Assumptions!$C$101,1,0) -> 2 | Q21: =1+IF(15>=Assumptions!$C$100,1,0)+IF(15>=Assumptions!$C$101,1,0) -> 2 | R21: =1+IF(16>=Assumptions!$C$100,1,0)+IF(16>=Assumptions!$C$101,1,0) -> 2 | S21: =1+IF(17>=Assumptions!$C$100,1,0)+IF(17>=Assumptions!$C$101,1,0) -> 2 | T21: =1+IF(18>=Assumptions!$C$100,1,0)+IF(18>=Assumptions!$C$101,1,0) -> 2 | U21: =1+IF(19>=Assumptions!$C$100,1,0)+IF(19>=Assumptions!$C$101,1,0) -> 2 | V21: =1+IF(20>=Assumptions!$C$100,1,0)+IF(20>=Assumptions!$C$101,1,0) -> 2 | W21: =1+IF(21>=Assumptions!$C$100,1,0)+IF(21>=Assumptions!$C$101,1,0) -> 2 | X21: =1+IF(22>=Assumptions!$C$100,1,0)+IF(22>=Assumptions!$C$101,1,0) -> 2 | Y21: =1+IF(23>=Assumptions!$C$100,1,0)+IF(23>=Assumptions!$C$101,1,0) -> 2 | Z21: =1+IF(24>=Assumptions!$C$100,1,0)+IF(24>=Assumptions!$C$101,1,0) -> 2 | AA21: =1+IF(25>=Assumptions!$C$100,1,0)+IF(25>=Assumptions!$C$101,1,0) -> 3 | AB21: =1+IF(26>=Assumptions!$C$100,1,0)+IF(26>=Assumptions!$C$101,1,0) -> 3 | AC21: =1+IF(27>=Assumptions!$C$100,1,0)+IF(27>=Assumptions!$C$101,1,0) -> 3 | AD21: =1+IF(28>=Assumptions!$C$100,1,0)+IF(28>=Assumptions!$C$101,1,0) -> 3 | AE21: =1+IF(29>=Assumptions!$C$100,1,0)+IF(29>=Assumptions!$C$101,1,0) -> 3 | AF21: =1+IF(30>=Assumptions!$C$100,1,0)+IF(30>=Assumptions!$C$101,1,0) -> 3
B22: Regional price multiplier | C22: =1+IF(1>=Assumptions!$C$100,1,0)*Assumptions!$C$104*Assumptions!$C$102+IF(1>=Assumptions!$C$101,1,0)*Assumptions!$C$105*Assumptions!$C$103 -> 1 | D22: =1+IF(2>=Assumptions!$C$100,1,0)*Assumptions!$C$104*Assumptions!$C$102+IF(2>=Assumptions!$C$101,1,0)*Assumptions!$C$105*Assumptions!$C$103 -> 1 | E22: =1+IF(3>=Assumptions!$C$100,1,0)*Assumptions!$C$104*Assumptions!$C$102+IF(3>=Assumptions!$C$101,1,0)*Assumptions!$C$105*Assumptions!$C$103 -> 1 | F22: =1+IF(4>=Assumptions!$C$100,1,0)*Assumptions!$C$104*Assumptions!$C$102+IF(4>=Assumptions!$C$101,1,0)*Assumptions!$C$105*Assumptions!$C$103 -> 1 | G22: =1+IF(5>=Assumptions!$C$100,1,0)*Assumptions!$C$104*Assumptions!$C$102+IF(5>=Assumptions!$C$101,1,0)*Assumptions!$C$105*Assumptions!$C$103 -> 1 | H22: =1+IF(6>=Assumptions!$C$100,1,0)*Assumptions!$C$104*Assumptions!$C$102+IF(6>=Assumptions!$C$101,1,0)*Assumptions!$C$105*Assumptions!$C$103 -> 1 | I22: =1+IF(7>=Assumptions!$C$100,1,0)*Assumptions!$C$104*Assumptions!$C$102+IF(7>=Assumptions!$C$101,1,0)*Assumptions!$C$105*Assumptions!$C$103 -> 1 | J22: =1+IF(8>=Assumptions!$C$100,1,0)*Assumptions!$C$104*Assumptions!$C$102+IF(8>=Assumptions!$C$101,1,0)*Assumptions!$C$105*Assumptions!$C$103 -> 1 | K22: =1+IF(9>=Assumptions!$C$100,1,0)*Assumptions!$C$104*Assumptions!$C$102+IF(9>=Assumptions!$C$101,1,0)*Assumptions!$C$105*Assumptions!$C$103 -> 1 | L22: =1+IF(10>=Assumptions!$C$100,1,0)*Assumptions!$C$104*Assumptions!$C$102+IF(10>=Assumptions!$C$101,1,0)*Assumptions!$C$105*Assumptions!$C$103 -> 1 | M22: =1+IF(11>=Assumptions!$C$100,1,0)*Assumptions!$C$104*Assumptions!$C$102+IF(11>=Assumptions!$C$101,1,0)*Assumptions!$C$105*Assumptions!$C$103 -> 1 | N22: =1+IF(12>=Assumptions!$C$100,1,0)*Assumptions!$C$104*Assumptions!$C$102+IF(12>=Assumptions!$C$101,1,0)*Assumptions!$C$105*Assumptions!$C$103 -> 1 | O22: =1+IF(13>=Assumptions!$C$100,1,0)*Assumptions!$C$104*Assumptions!$C$102+IF(13>=Assumptions!$C$101,1,0)*Assumptions!$C$105*Assumptions!$C$103 -> 1.02 | P22: =1+IF(14>=Assumptions!$C$100,1,0)*Assumptions!$C$104*Assumptions!$C$102+IF(14>=Assumptions!$C$101,1,0)*Assumptions!$C$105*Assumptions!$C$103 -> 1.02 | Q22: =1+IF(15>=Assumptions!$C$100,1,0)*Assumptions!$C$104*Assumptions!$C$102+IF(15>=Assumptions!$C$101,1,0)*Assumptions!$C$105*Assumptions!$C$103 -> 1.02 | R22: =1+IF(16>=Assumptions!$C$100,1,0)*Assumptions!$C$104*Assumptions!$C$102+IF(16>=Assumptions!$C$101,1,0)*Assumptions!$C$105*Assumptions!$C$103 -> 1.02 | S22: =1+IF(17>=Assumptions!$C$100,1,0)*Assumptions!$C$104*Assumptions!$C$102+IF(17>=Assumptions!$C$101,1,0)*Assumptions!$C$105*Assumptions!$C$103 -> 1.02 | T22: =1+IF(18>=Assumptions!$C$100,1,0)*Assumptions!$C$104*Assumptions!$C$102+IF(18>=Assumptions!$C$101,1,0)*Assumptions!$C$105*Assumptions!$C$103 -> 1.02 | U22: =1+IF(19>=Assumptions!$C$100,1,0)*Assumptions!$C$104*Assumptions!$C$102+IF(19>=Assumptions!$C$101,1,0)*Assumptions!$C$105*Assumptions!$C$103 -> 1.02 | V22: =1+IF(20>=Assumptions!$C$100,1,0)*Assumptions!$C$104*Assumptions!$C$102+IF(20>=Assumptions!$C$101,1,0)*Assumptions!$C$105*Assumptions!$C$103 -> 1.02 | W22: =1+IF(21>=Assumptions!$C$100,1,0)*Assumptions!$C$104*Assumptions!$C$102+IF(21>=Assumptions!$C$101,1,0)*Assumptions!$C$105*Assumptions!$C$103 -> 1.02 | X22: =1+IF(22>=Assumptions!$C$100,1,0)*Assumptions!$C$104*Assumptions!$C$102+IF(22>=Assumptions!$C$101,1,0)*Assumptions!$C$105*Assumptions!$C$103 -> 1.02 | Y22: =1+IF(23>=Assumptions!$C$100,1,0)*Assumptions!$C$104*Assumptions!$C$102+IF(23>=Assumptions!$C$101,1,0)*Assumptions!$C$105*Assumptions!$C$103 -> 1.02 | Z22: =1+IF(24>=Assumptions!$C$100,1,0)*Assumptions!$C$104*Assumptions!$C$102+IF(24>=Assumptions!$C$101,1,0)*Assumptions!$C$105*Assumptions!$C$103 -> 1.02 | AA22: =1+IF(25>=Assumptions!$C$100,1,0)*Assumptions!$C$104*Assumptions!$C$102+IF(25>=Assumptions!$C$101,1,0)*Assumptions!$C$105*Assumptions!$C$103 -> 1.047 | AB22: =1+IF(26>=Assumptions!$C$100,1,0)*Assumptions!$C$104*Assumptions!$C$102+IF(26>=Assumptions!$C$101,1,0)*Assumptions!$C$105*Assumptions!$C$103 -> 1.047 | AC22: =1+IF(27>=Assumptions!$C$100,1,0)*Assumptions!$C$104*Assumptions!$C$102+IF(27>=Assumptions!$C$101,1,0)*Assumptions!$C$105*Assumptions!$C$103 -> 1.047 | AD22: =1+IF(28>=Assumptions!$C$100,1,0)*Assumptions!$C$104*Assumptions!$C$102+IF(28>=Assumptions!$C$101,1,0)*Assumptions!$C$105*Assumptions!$C$103 -> 1.047 | AE22: =1+IF(29>=Assumptions!$C$100,1,0)*Assumptions!$C$104*Assumptions!$C$102+IF(29>=Assumptions!$C$101,1,0)*Assumptions!$C$105*Assumptions!$C$103 -> 1.047 | AF22: =1+IF(30>=Assumptions!$C$100,1,0)*Assumptions!$C$104*Assumptions!$C$102+IF(30>=Assumptions!$C$101,1,0)*Assumptions!$C$105*Assumptions!$C$103 -> 1.047
B23: Environment weight | C23: =1+Assumptions!$C$10*(Assumptions!$C$9-1) -> 2 | D23: =1+Assumptions!$C$10*(Assumptions!$C$9-1) -> 2 | E23: =1+Assumptions!$C$10*(Assumptions!$C$9-1) -> 2 | F23: =1+Assumptions!$C$10*(Assumptions!$C$9-1) -> 2 | G23: =1+Assumptions!$C$10*(Assumptions!$C$9-1) -> 2 | H23: =1+Assumptions!$C$10*(Assumptions!$C$9-1) -> 2 | I23: =1+Assumptions!$C$10*(Assumptions!$C$9-1) -> 2 | J23: =1+Assumptions!$C$10*(Assumptions!$C$9-1) -> 2 | ... AF23: =1+Assumptions!$C$10*(Assumptions!$C$9-1) -> 2
B24: Env-region deployments (clusters) | C24: =C21+Assumptions!$C$9-1 -> 3 | D24: =D21+Assumptions!$C$9-1 -> 3 | E24: =E21+Assumptions!$C$9-1 -> 3 | F24: =F21+Assumptions!$C$9-1 -> 3 | G24: =G21+Assumptions!$C$9-1 -> 3 | H24: =H21+Assumptions!$C$9-1 -> 3 | I24: =I21+Assumptions!$C$9-1 -> 3 | J24: =J21+Assumptions!$C$9-1 -> 3 | ... AF24: =AF21+Assumptions!$C$9-1 -> 5

Sheet Costs
B1: Monthly Cost Build ($)
B2: Black = calculation. Subtotals by consumption pillar. Figures are list price (no partner discounts).
B4: Month | C4: M1 | D4: M2 | E4: M3 | F4: M4 | G4: M5 | H4: M6 | I4: M7 | J4: M8 | K4: M9 | L4: M10 | M4: M11 | N4: M12 | O4: M13 | P4: M14 | Q4: M15 | R4: M16 | S4: M17 | T4: M18 | U4: M19 | V4: M20 | W4: M21 | X4: M22 | Y4: M23 | Z4: M24 | AA4: M25 | AB4: M26 | AC4: M27 | AD4: M28 | AE4: M29 | AF4: M30
B5: COMPUTE - Amazon EKS
B6: EKS control plane (per env, per region) | C6: =Assumptions!$C$43*730*Drivers!C24 -> 219 | D6: =Assumptions!$C$43*730*Drivers!D24 -> 219 | E6: =Assumptions!$C$43*730*Drivers!E24 -> 219 | F6: =Assumptions!$C$43*730*Drivers!F24 -> 219 | G6: =Assumptions!$C$43*730*Drivers!G24 -> 219 | H6: =Assumptions!$C$43*730*Drivers!H24 -> 219 | I6: =Assumptions!$C$43*730*Drivers!I24 -> 219 | J6: =Assumptions!$C$43*730*Drivers!J24 -> 219 | ... AF6: =Assumptions!$C$43*730*Drivers!AF24 -> 365
B7: EKS worker nodes (prod scales; dev/stage baseline) | C7: =(MAX(Assumptions!$C$45,ROUNDUP(Drivers!C8/Assumptions!$C$44,0))*Drivers!C22+Assumptions!$C$45*Assumptions!$C$10*(Assumptions!$C$9-1))*Assumptions!$C$46*730*(1-Assumptions!$C$47) -> 840.96 | D7: =(MAX(Assumptions!$C$45,ROUNDUP(Drivers!D8/Assumptions!$C$44,0))*Drivers!D22+Assumptions!$C$45*Assumptions!$C$10*(Assumptions!$C$9-1))*Assumptions!$C$46*730*(1-Assumptions!$C$47) -> 840.96 | E7: =(MAX(Assumptions!$C$45,ROUNDUP(Drivers!E8/Assumptions!$C$44,0))*Drivers!E22+Assumptions!$C$45*Assumptions!$C$10*(Assumptions!$C$9-1))*Assumptions!$C$46*730*(1-Assumptions!$C$47) -> 840.96 | F7: =(MAX(Assumptions!$C$45,ROUNDUP(Drivers!F8/Assumptions!$C$44,0))*Drivers!F22+Assumptions!$C$45*Assumptions!$C$10*(Assumptions!$C$9-1))*Assumptions!$C$46*730*(1-Assumptions!$C$47) -> 840.96 | G7: =(MAX(Assumptions!$C$45,ROUNDUP(Drivers!G8/Assumptions!$C$44,0))*Drivers!G22+Assumptions!$C$45*Assumptions!$C$10*(Assumptions!$C$9-1))*Assumptions!$C$46*730*(1-Assumptions!$C$47) -> 840.96 | H7: =(MAX(Assumptions!$C$45,ROUNDUP(Drivers!H8/Assumptions!$C$44,0))*Drivers!H22+Assumptions!$C$45*Assumptions!$C$10*(Assumptions!$C$9-1))*Assumptions!$C$46*730*(1-Assumptions!$C$47) -> 840.96 | I7: =(MAX(Assumptions!$C$45,ROUNDUP(Drivers!I8/Assumptions!$C$44,0))*Drivers!I22+Assumptions!$C$45*Assumptions!$C$10*(Assumptions!$C$9-1))*Assumptions!$C$46*730*(1-Assumptions!$C$47) -> 840.96 | J7: =(MAX(Assumptions!$C$45,ROUNDUP(Drivers!J8/Assumptions!$C$44,0))*Drivers!J22+Assumptions!$C$45*Assumptions!$C$10*(Assumptions!$C$9-1))*Assumptions!$C$46*730*(1-Assumptions!$C$47) -> 840.96 | ... AF7: =(MAX(Assumptions!$C$45,ROUNDUP(Drivers!AF8/Assumptions!$C$44,0))*Drivers!AF22+Assumptions!$C$45*Assumptions!$C$10*(Assumptions!$C$9-1))*Assumptions!$C$46*730*(1-Assumptions!$C$47) -> 5043.0269
B8: Observability (CloudWatch, Prometheus, Grafana, X-Ray; all envs) | C8: =(Assumptions!$C$48+Assumptions!$C$108)*(1+Assumptions!$C$111)+Drivers!C18*(Assumptions!$C$49+Assumptions!$C$109)+Assumptions!$C$110 -> 783.02784 | D8: =(Assumptions!$C$48+Assumptions!$C$108)*(1+Assumptions!$C$111)+Drivers!D18*(Assumptions!$C$49+Assumptions!$C$109)+Assumptions!$C$110 -> 786.81264 | E8: =(Assumptions!$C$48+Assumptions!$C$108)*(1+Assumptions!$C$111)+Drivers!E18*(Assumptions!$C$49+Assumptions!$C$109)+Assumptions!$C$110 -> 792.11136 | F8: =(Assumptions!$C$48+Assumptions!$C$108)*(1+Assumptions!$C$111)+Drivers!F18*(Assumptions!$C$49+Assumptions!$C$109)+Assumptions!$C$110 -> 799.68096 | G8: =(Assumptions!$C$48+Assumptions!$C$108)*(1+Assumptions!$C$111)+Drivers!G18*(Assumptions!$C$49+Assumptions!$C$109)+Assumptions!$C$110 -> 808.386 | H8: =(Assumptions!$C$48+Assumptions!$C$108)*(1+Assumptions!$C$111)+Drivers!H18*(Assumptions!$C$49+Assumptions!$C$109)+Assumptions!$C$110 -> 817.848 | I8: =(Assumptions!$C$48+Assumptions!$C$108)*(1+Assumptions!$C$111)+Drivers!I18*(Assumptions!$C$49+Assumptions!$C$109)+Assumptions!$C$110 -> 836.772 | J8: =(Assumptions!$C$48+Assumptions!$C$108)*(1+Assumptions!$C$111)+Drivers!J18*(Assumptions!$C$49+Assumptions!$C$109)+Assumptions!$C$110 -> 867.0504 | ... AF8: =(Assumptions!$C$48+Assumptions!$C$108)*(1+Assumptions!$C$111)+Drivers!AF18*(Assumptions!$C$49+Assumptions!$C$109)+Assumptions!$C$110 -> 2672.4
B9: Platform/management baseline (all envs) | C9: =Assumptions!$C$50*Drivers!C23 -> 1700 | D9: =Assumptions!$C$50*Drivers!D23 -> 1700 | E9: =Assumptions!$C$50*Drivers!E23 -> 1700 | F9: =Assumptions!$C$50*Drivers!F23 -> 1700 | G9: =Assumptions!$C$50*Drivers!G23 -> 1700 | H9: =Assumptions!$C$50*Drivers!H23 -> 1700 | I9: =Assumptions!$C$50*Drivers!I23 -> 1700 | J9: =Assumptions!$C$50*Drivers!J23 -> 1700 | ... AF9: =Assumptions!$C$50*Drivers!AF23 -> 1700
B10: Reserved/standby capacity (launch readiness + DR) | C10: =Assumptions!$C$51*Drivers!C23 -> 1300 | D10: =Assumptions!$C$51*Drivers!D23 -> 1300 | E10: =Assumptions!$C$51*Drivers!E23 -> 1300 | F10: =Assumptions!$C$51*Drivers!F23 -> 1300 | G10: =Assumptions!$C$51*Drivers!G23 -> 1300 | H10: =Assumptions!$C$51*Drivers!H23 -> 1300 | I10: =Assumptions!$C$51*Drivers!I23 -> 1300 | J10: =Assumptions!$C$51*Drivers!J23 -> 1300 | ... AF10: =Assumptions!$C$51*Drivers!AF23 -> 1300
B11: Compute subtotal | C11: =C6+C7+C8+C9+C10 -> 4842.9878 | D11: =D6+D7+D8+D9+D10 -> 4846.7726 | E11: =E6+E7+E8+E9+E10 -> 4852.0714 | F11: =F6+F7+F8+F9+F10 -> 4859.641 | G11: =G6+G7+G8+G9+G10 -> 4868.346 | H11: =H6+H7+H8+H9+H10 -> 4877.808 | I11: =I6+I7+I8+I9+I10 -> 4896.732 | J11: =J6+J7+J8+J9+J10 -> 4927.0104 | ... AF11: =AF6+AF7+AF8+AF9+AF10 -> 11080.427
B12: SECURITY - Cognito + WAF
B13: Cognito (monthly active users, tiered) | C13: =MAX(0,MIN(Drivers!C9,100000)-Assumptions!$C$53)*Assumptions!$C$54+MAX(0,MIN(Drivers!C9,1000000)-100000)*Assumptions!$C$55+MAX(0,MIN(Drivers!C9,10000000)-1000000)*Assumptions!$C$56+MAX(0,Drivers!C9-10000000)*Assumptions!$C$57 -> 0 | D13: =MAX(0,MIN(Drivers!D9,100000)-Assumptions!$C$53)*Assumptions!$C$54+MAX(0,MIN(Drivers!D9,1000000)-100000)*Assumptions!$C$55+MAX(0,MIN(Drivers!D9,10000000)-1000000)*Assumptions!$C$56+MAX(0,Drivers!D9-10000000)*Assumptions!$C$57 -> 0 | E13: =MAX(0,MIN(Drivers!E9,100000)-Assumptions!$C$53)*Assumptions!$C$54+MAX(0,MIN(Drivers!E9,1000000)-100000)*Assumptions!$C$55+MAX(0,MIN(Drivers!E9,10000000)-1000000)*Assumptions!$C$56+MAX(0,Drivers!E9-10000000)*Assumptions!$C$57 -> 0 | F13: =MAX(0,MIN(Drivers!F9,100000)-Assumptions!$C$53)*Assumptions!$C$54+MAX(0,MIN(Drivers!F9,1000000)-100000)*Assumptions!$C$55+MAX(0,MIN(Drivers!F9,10000000)-1000000)*Assumptions!$C$56+MAX(0,Drivers!F9-10000000)*Assumptions!$C$57 -> 0 | G13: =MAX(0,MIN(Drivers!G9,100000)-Assumptions!$C$53)*Assumptions!$C$54+MAX(0,MIN(Drivers!G9,1000000)-100000)*Assumptions!$C$55+MAX(0,MIN(Drivers!G9,10000000)-1000000)*Assumptions!$C$56+MAX(0,Drivers!G9-10000000)*Assumptions!$C$57 -> 0 | H13: =MAX(0,MIN(Drivers!H9,100000)-Assumptions!$C$53)*Assumptions!$C$54+MAX(0,MIN(Drivers!H9,1000000)-100000)*Assumptions!$C$55+MAX(0,MIN(Drivers!H9,10000000)-1000000)*Assumptions!$C$56+MAX(0,Drivers!H9-10000000)*Assumptions!$C$57 -> 0 | I13: =MAX(0,MIN(Drivers!I9,100000)-Assumptions!$C$53)*Assumptions!$C$54+MAX(0,MIN(Drivers!I9,1000000)-100000)*Assumptions!$C$55+MAX(0,MIN(Drivers!I9,10000000)-1000000)*Assumptions!$C$56+MAX(0,Drivers!I9-10000000)*Assumptions!$C$57 -> 96.25 | J13: =MAX(0,MIN(Drivers!J9,100000)-Assumptions!$C$53)*Assumptions!$C$54+MAX(0,MIN(Drivers!J9,1000000)-100000)*Assumptions!$C$55+MAX(0,MIN(Drivers!J9,10000000)-1000000)*Assumptions!$C$56+MAX(0,Drivers!J9-10000000)*Assumptions!$C$57 -> 291.1 | ... AF13: =MAX(0,MIN(Drivers!AF9,100000)-Assumptions!$C$53)*Assumptions!$C$54+MAX(0,MIN(Drivers!AF9,1000000)-100000)*Assumptions!$C$55+MAX(0,MIN(Drivers!AF9,10000000)-1000000)*Assumptions!$C$56+MAX(0,Drivers!AF9-10000000)*Assumptions!$C$57 -> 8477.5
B14: WAF (ACL per env + request inspection) | C14: =Assumptions!$C$58*Drivers!C24+Drivers!C18*Assumptions!$C$59 -> 77.1888 | D14: =Assumptions!$C$58*Drivers!D24+Drivers!D18*Assumptions!$C$59 -> 79.9248 | E14: =Assumptions!$C$58*Drivers!E24+Drivers!E18*Assumptions!$C$59 -> 83.7552 | F14: =Assumptions!$C$58*Drivers!F24+Drivers!F18*Assumptions!$C$59 -> 89.2272 | G14: =Assumptions!$C$58*Drivers!G24+Drivers!G18*Assumptions!$C$59 -> 95.52 | H14: =Assumptions!$C$58*Drivers!H24+Drivers!H18*Assumptions!$C$59 -> 102.36 | I14: =Assumptions!$C$58*Drivers!I24+Drivers!I18*Assumptions!$C$59 -> 116.04 | J14: =Assumptions!$C$58*Drivers!J24+Drivers!J18*Assumptions!$C$59 -> 137.928 | ... AF14: =Assumptions!$C$58*Drivers!AF24+Drivers!AF18*Assumptions!$C$59 -> 1493
B15: Security subtotal | C15: =C13+C14 -> 77.1888 | D15: =D13+D14 -> 79.9248 | E15: =E13+E14 -> 83.7552 | F15: =F13+F14 -> 89.2272 | G15: =G13+G14 -> 95.52 | H15: =H13+H14 -> 102.36 | I15: =I13+I14 -> 212.29 | J15: =J13+J14 -> 429.028 | ... AF15: =AF13+AF14 -> 9970.5
B16: NETWORKING - ALB + data transfer
B17: ALB (per env, per region) | C17: =Assumptions!$C$61*Assumptions!$C$62*730*Drivers!C24 -> 98.55 | D17: =Assumptions!$C$61*Assumptions!$C$62*730*Drivers!D24 -> 98.55 | E17: =Assumptions!$C$61*Assumptions!$C$62*730*Drivers!E24 -> 98.55 | F17: =Assumptions!$C$61*Assumptions!$C$62*730*Drivers!F24 -> 98.55 | G17: =Assumptions!$C$61*Assumptions!$C$62*730*Drivers!G24 -> 98.55 | H17: =Assumptions!$C$61*Assumptions!$C$62*730*Drivers!H24 -> 98.55 | I17: =Assumptions!$C$61*Assumptions!$C$62*730*Drivers!I24 -> 98.55 | J17: =Assumptions!$C$61*Assumptions!$C$62*730*Drivers!J24 -> 98.55 | ... AF17: =Assumptions!$C$61*Assumptions!$C$62*730*Drivers!AF24 -> 164.25
B18: NAT gateways (per env, per region) | C18: =Assumptions!$C$65*Assumptions!$C$66*730*Drivers!C24 -> 197.1 | D18: =Assumptions!$C$65*Assumptions!$C$66*730*Drivers!D24 -> 197.1 | E18: =Assumptions!$C$65*Assumptions!$C$66*730*Drivers!E24 -> 197.1 | F18: =Assumptions!$C$65*Assumptions!$C$66*730*Drivers!F24 -> 197.1 | G18: =Assumptions!$C$65*Assumptions!$C$66*730*Drivers!G24 -> 197.1 | H18: =Assumptions!$C$65*Assumptions!$C$66*730*Drivers!H24 -> 197.1 | I18: =Assumptions!$C$65*Assumptions!$C$66*730*Drivers!I24 -> 197.1 | J18: =Assumptions!$C$65*Assumptions!$C$66*730*Drivers!J24 -> 197.1 | ... AF18: =Assumptions!$C$65*Assumptions!$C$66*730*Drivers!AF24 -> 328.5
B19: ALB LCU (request volume) | C19: =Drivers!C18*Assumptions!$C$63*Drivers!C22 -> 0.3648 | D19: =Drivers!D18*Assumptions!$C$63*Drivers!D22 -> 0.8208 | E19: =Drivers!E18*Assumptions!$C$63*Drivers!E22 -> 1.4592 | F19: =Drivers!F18*Assumptions!$C$63*Drivers!F22 -> 2.3712 | G19: =Drivers!G18*Assumptions!$C$63*Drivers!G22 -> 3.42 | H19: =Drivers!H18*Assumptions!$C$63*Drivers!H22 -> 4.56 | I19: =Drivers!I18*Assumptions!$C$63*Drivers!I22 -> 6.84 | J19: =Drivers!J18*Assumptions!$C$63*Drivers!J22 -> 10.488 | ... AF19: =Drivers!AF18*Assumptions!$C$63*Drivers!AF22 -> 238.716
B20: Data transfer out | C20: =Drivers!C17*Assumptions!$C$64*Drivers!C22 -> 20.039062 | D20: =Drivers!D17*Assumptions!$C$64*Drivers!D22 -> 45.087891 | E20: =Drivers!E17*Assumptions!$C$64*Drivers!E22 -> 80.15625 | F20: =Drivers!F17*Assumptions!$C$64*Drivers!F22 -> 130.25391 | G20: =Drivers!G17*Assumptions!$C$64*Drivers!G22 -> 187.86621 | H20: =Drivers!H17*Assumptions!$C$64*Drivers!H22 -> 250.48828 | I20: =Drivers!I17*Assumptions!$C$64*Drivers!I22 -> 375.73242 | J20: =Drivers!J17*Assumptions!$C$64*Drivers!J22 -> 576.12305 | ... AF20: =Drivers!AF17*Assumptions!$C$64*Drivers!AF22 -> 13113.062
B21: Networking subtotal | C21: =C17+C18+C19+C20 -> 316.05386 | D21: =D17+D18+D19+D20 -> 341.55869 | E21: =E17+E18+E19+E20 -> 377.26545 | F21: =F17+F18+F19+F20 -> 428.27511 | G21: =G17+G18+G19+G20 -> 486.93621 | H21: =H17+H18+H19+H20 -> 550.69828 | I21: =I17+I18+I19+I20 -> 678.22242 | J21: =J17+J18+J19+J20 -> 882.26105 | ... AF21: =AF17+AF18+AF19+AF20 -> 13844.528
B22: DATABASE - DynamoDB + Aurora
B23: Aurora compute (prod scales; dev/stage baseline) | C23: =(MAX(Assumptions!$C$69,Drivers!C8/Assumptions!$C$68)*Drivers!C22+Assumptions!$C$70*(Assumptions!$C$9-1))*Assumptions!$C$71*730 -> 1051.2 | D23: =(MAX(Assumptions!$C$69,Drivers!D8/Assumptions!$C$68)*Drivers!D22+Assumptions!$C$70*(Assumptions!$C$9-1))*Assumptions!$C$71*730 -> 1051.2 | E23: =(MAX(Assumptions!$C$69,Drivers!E8/Assumptions!$C$68)*Drivers!E22+Assumptions!$C$70*(Assumptions!$C$9-1))*Assumptions!$C$71*730 -> 1051.2 | F23: =(MAX(Assumptions!$C$69,Drivers!F8/Assumptions!$C$68)*Drivers!F22+Assumptions!$C$70*(Assumptions!$C$9-1))*Assumptions!$C$71*730 -> 1051.2 | G23: =(MAX(Assumptions!$C$69,Drivers!G8/Assumptions!$C$68)*Drivers!G22+Assumptions!$C$70*(Assumptions!$C$9-1))*Assumptions!$C$71*730 -> 1051.2 | H23: =(MAX(Assumptions!$C$69,Drivers!H8/Assumptions!$C$68)*Drivers!H22+Assumptions!$C$70*(Assumptions!$C$9-1))*Assumptions!$C$71*730 -> 1051.2 | I23: =(MAX(Assumptions!$C$69,Drivers!I8/Assumptions!$C$68)*Drivers!I22+Assumptions!$C$70*(Assumptions!$C$9-1))*Assumptions!$C$71*730 -> 1051.2 | J23: =(MAX(Assumptions!$C$69,Drivers!J8/Assumptions!$C$68)*Drivers!J22+Assumptions!$C$70*(Assumptions!$C$9-1))*Assumptions!$C$71*730 -> 1051.2 | ... AF23: =(MAX(Assumptions!$C$69,Drivers!AF8/Assumptions!$C$68)*Drivers!AF22+Assumptions!$C$70*(Assumptions!$C$9-1))*Assumptions!$C$71*730 -> 4761.06
B24: Aurora storage | C24: =Drivers!C7/1000*Assumptions!$C$73*Assumptions!$C$72*Drivers!C22 -> 0.4 | D24: =Drivers!D7/1000*Assumptions!$C$73*Assumptions!$C$72*Drivers!D22 -> 0.9 | E24: =Drivers!E7/1000*Assumptions!$C$73*Assumptions!$C$72*Drivers!E22 -> 1.6 | F24: =Drivers!F7/1000*Assumptions!$C$73*Assumptions!$C$72*Drivers!F22 -> 2.6 | G24: =Drivers!G7/1000*Assumptions!$C$73*Assumptions!$C$72*Drivers!G22 -> 3.75 | H24: =Drivers!H7/1000*Assumptions!$C$73*Assumptions!$C$72*Drivers!H22 -> 5 | I24: =Drivers!I7/1000*Assumptions!$C$73*Assumptions!$C$72*Drivers!I22 -> 7.5 | J24: =Drivers!J7/1000*Assumptions!$C$73*Assumptions!$C$72*Drivers!J22 -> 11.5 | ... AF24: =Drivers!AF7/1000*Assumptions!$C$73*Assumptions!$C$72*Drivers!AF22 -> 261.75
B25: ElastiCache (Redis, all envs) | C25: =Assumptions!$C$81*Drivers!C23 -> 1300 | D25: =Assumptions!$C$81*Drivers!D23 -> 1300 | E25: =Assumptions!$C$81*Drivers!E23 -> 1300 | F25: =Assumptions!$C$81*Drivers!F23 -> 1300 | G25: =Assumptions!$C$81*Drivers!G23 -> 1300 | H25: =Assumptions!$C$81*Drivers!H23 -> 1300 | I25: =Assumptions!$C$81*Drivers!I23 -> 1300 | J25: =Assumptions!$C$81*Drivers!J23 -> 1300 | ... AF25: =Assumptions!$C$81*Drivers!AF23 -> 1300
B26: OpenSearch (search + logs, all envs) | C26: =Assumptions!$C$82*Drivers!C23 -> 1300 | D26: =Assumptions!$C$82*Drivers!D23 -> 1300 | E26: =Assumptions!$C$82*Drivers!E23 -> 1300 | F26: =Assumptions!$C$82*Drivers!F23 -> 1300 | G26: =Assumptions!$C$82*Drivers!G23 -> 1300 | H26: =Assumptions!$C$82*Drivers!H23 -> 1300 | I26: =Assumptions!$C$82*Drivers!I23 -> 1300 | J26: =Assumptions!$C$82*Drivers!J23 -> 1300 | ... AF26: =Assumptions!$C$82*Drivers!AF23 -> 1300
B27: DynamoDB writes | C27: =Drivers!C11*Assumptions!$C$75/1000000*Assumptions!$C$77*Drivers!C22 -> 0.2128 | D27: =Drivers!D11*Assumptions!$C$75/1000000*Assumptions!$C$77*Drivers!D22 -> 0.4788 | E27: =Drivers!E11*Assumptions!$C$75/1000000*Assumptions!$C$77*Drivers!E22 -> 0.8512 | F27: =Drivers!F11*Assumptions!$C$75/1000000*Assumptions!$C$77*Drivers!F22 -> 1.3832 | G27: =Drivers!G11*Assumptions!$C$75/1000000*Assumptions!$C$77*Drivers!G22 -> 1.995 | H27: =Drivers!H11*Assumptions!$C$75/1000000*Assumptions!$C$77*Drivers!H22 -> 2.66 | I27: =Drivers!I11*Assumptions!$C$75/1000000*Assumptions!$C$77*Drivers!I22 -> 3.99 | J27: =Drivers!J11*Assumptions!$C$75/1000000*Assumptions!$C$77*Drivers!J22 -> 6.118 | ... AF27: =Drivers!AF11*Assumptions!$C$75/1000000*Assumptions!$C$77*Drivers!AF22 -> 139.251
B28: DynamoDB reads | C28: =Drivers!C8*Assumptions!$C$76*30.4/1000000*Assumptions!$C$78*Drivers!C22 -> 0.608 | D28: =Drivers!D8*Assumptions!$C$76*30.4/1000000*Assumptions!$C$78*Drivers!D22 -> 1.368 | E28: =Drivers!E8*Assumptions!$C$76*30.4/1000000*Assumptions!$C$78*Drivers!E22 -> 2.432 | F28: =Drivers!F8*Assumptions!$C$76*30.4/1000000*Assumptions!$C$78*Drivers!F22 -> 3.952 | G28: =Drivers!G8*Assumptions!$C$76*30.4/1000000*Assumptions!$C$78*Drivers!G22 -> 5.7 | H28: =Drivers!H8*Assumptions!$C$76*30.4/1000000*Assumptions!$C$78*Drivers!H22 -> 7.6 | I28: =Drivers!I8*Assumptions!$C$76*30.4/1000000*Assumptions!$C$78*Drivers!I22 -> 11.4 | J28: =Drivers!J8*Assumptions!$C$76*30.4/1000000*Assumptions!$C$78*Drivers!J22 -> 17.48 | ... AF28: =Drivers!AF8*Assumptions!$C$76*30.4/1000000*Assumptions!$C$78*Drivers!AF22 -> 397.86
B29: DynamoDB storage | C29: =Drivers!C7/1000*Assumptions!$C$80*Assumptions!$C$79*Drivers!C22 -> 0.6 | D29: =Drivers!D7/1000*Assumptions!$C$80*Assumptions!$C$79*Drivers!D22 -> 1.35 | E29: =Drivers!E7/1000*Assumptions!$C$80*Assumptions!$C$79*Drivers!E22 -> 2.4 | F29: =Drivers!F7/1000*Assumptions!$C$80*Assumptions!$C$79*Drivers!F22 -> 3.9 | G29: =Drivers!G7/1000*Assumptions!$C$80*Assumptions!$C$79*Drivers!G22 -> 5.625 | H29: =Drivers!H7/1000*Assumptions!$C$80*Assumptions!$C$79*Drivers!H22 -> 7.5 | I29: =Drivers!I7/1000*Assumptions!$C$80*Assumptions!$C$79*Drivers!I22 -> 11.25 | J29: =Drivers!J7/1000*Assumptions!$C$80*Assumptions!$C$79*Drivers!J22 -> 17.25 | ... AF29: =Drivers!AF7/1000*Assumptions!$C$80*Assumptions!$C$79*Drivers!AF22 -> 392.625
B30: Database subtotal | C30: =C23+C24+C25+C26+C27+C28+C29 -> 3653.0208 | D30: =D23+D24+D25+D26+D27+D28+D29 -> 3655.2968 | E30: =E23+E24+E25+E26+E27+E28+E29 -> 3658.4832 | F30: =F23+F24+F25+F26+F27+F28+F29 -> 3663.0352 | G30: =G23+G24+G25+G26+G27+G28+G29 -> 3668.27 | H30: =H23+H24+H25+H26+H27+H28+H29 -> 3673.96 | I30: =I23+I24+I25+I26+I27+I28+I29 -> 3685.34 | J30: =J23+J24+J25+J26+J27+J28+J29 -> 3703.548 | ... AF30: =AF23+AF24+AF25+AF26+AF27+AF28+AF29 -> 8552.546
B31: STORAGE - Amazon S3
B32: S3 storage (cumulative media) | C32: =Drivers!C16*Assumptions!$C$84*Drivers!C22 -> 0.22059784 | D32: =Drivers!D16*Assumptions!$C$84*Drivers!D22 -> 0.71694298 | E32: =Drivers!E16*Assumptions!$C$84*Drivers!E22 -> 1.5993343 | F32: =Drivers!F16*Assumptions!$C$84*Drivers!F22 -> 3.0332203 | G32: =Drivers!G16*Assumptions!$C$84*Drivers!G22 -> 5.101325 | H32: =Drivers!H16*Assumptions!$C$84*Drivers!H22 -> 7.858798 | I32: =Drivers!I16*Assumptions!$C$84*Drivers!I22 -> 11.995008 | J32: =Drivers!J16*Assumptions!$C$84*Drivers!J22 -> 18.337195 | ... AF32: =Drivers!AF16*Assumptions!$C$84*Drivers!AF22 -> 1838.0558
B33: S3 requests (PUT + GET) | C33: =(Drivers!C11/1000*Assumptions!$C$85+Drivers!C8*Assumptions!$C$23*30.4/1000*Assumptions!$C$86)*Drivers!C22 -> 0.8208 | D33: =(Drivers!D11/1000*Assumptions!$C$85+Drivers!D8*Assumptions!$C$23*30.4/1000*Assumptions!$C$86)*Drivers!D22 -> 1.8468 | E33: =(Drivers!E11/1000*Assumptions!$C$85+Drivers!E8*Assumptions!$C$23*30.4/1000*Assumptions!$C$86)*Drivers!E22 -> 3.2832 | F33: =(Drivers!F11/1000*Assumptions!$C$85+Drivers!F8*Assumptions!$C$23*30.4/1000*Assumptions!$C$86)*Drivers!F22 -> 5.3352 | G33: =(Drivers!G11/1000*Assumptions!$C$85+Drivers!G8*Assumptions!$C$23*30.4/1000*Assumptions!$C$86)*Drivers!G22 -> 7.695 | H33: =(Drivers!H11/1000*Assumptions!$C$85+Drivers!H8*Assumptions!$C$23*30.4/1000*Assumptions!$C$86)*Drivers!H22 -> 10.26 | I33: =(Drivers!I11/1000*Assumptions!$C$85+Drivers!I8*Assumptions!$C$23*30.4/1000*Assumptions!$C$86)*Drivers!I22 -> 15.39 | J33: =(Drivers!J11/1000*Assumptions!$C$85+Drivers!J8*Assumptions!$C$23*30.4/1000*Assumptions!$C$86)*Drivers!J22 -> 23.598 | ... AF33: =(Drivers!AF11/1000*Assumptions!$C$85+Drivers!AF8*Assumptions!$C$23*30.4/1000*Assumptions!$C$86)*Drivers!AF22 -> 537.111
B34: Storage subtotal | C34: =C32+C33 -> 1.0413978 | D34: =D32+D33 -> 2.563743 | E34: =E32+E33 -> 4.8825343 | F34: =F32+F33 -> 8.3684203 | G34: =G32+G33 -> 12.796325 | H34: =H32+H33 -> 18.118798 | I34: =I32+I33 -> 27.385008 | J34: =J32+J33 -> 41.935195 | ... AF34: =AF32+AF33 -> 2375.1668
B35: AI APP - Bedrock + Claude
B36: Moderation (Haiku, every submission) | C36: =Drivers!C11*(Assumptions!$C$25/1000000*Assumptions!$C$33*(1-Assumptions!$C$39)+Assumptions!$C$26/1000000*Assumptions!$C$34)*(1+Assumptions!$C$41) -> 36.176 | D36: =Drivers!D11*(Assumptions!$C$25/1000000*Assumptions!$C$33*(1-Assumptions!$C$39)+Assumptions!$C$26/1000000*Assumptions!$C$34)*(1+Assumptions!$C$41) -> 81.396 | E36: =Drivers!E11*(Assumptions!$C$25/1000000*Assumptions!$C$33*(1-Assumptions!$C$39)+Assumptions!$C$26/1000000*Assumptions!$C$34)*(1+Assumptions!$C$41) -> 144.704 | F36: =Drivers!F11*(Assumptions!$C$25/1000000*Assumptions!$C$33*(1-Assumptions!$C$39)+Assumptions!$C$26/1000000*Assumptions!$C$34)*(1+Assumptions!$C$41) -> 235.144 | G36: =Drivers!G11*(Assumptions!$C$25/1000000*Assumptions!$C$33*(1-Assumptions!$C$39)+Assumptions!$C$26/1000000*Assumptions!$C$34)*(1+Assumptions!$C$41) -> 339.15 | H36: =Drivers!H11*(Assumptions!$C$25/1000000*Assumptions!$C$33*(1-Assumptions!$C$39)+Assumptions!$C$26/1000000*Assumptions!$C$34)*(1+Assumptions!$C$41) -> 452.2 | I36: =Drivers!I11*(Assumptions!$C$25/1000000*Assumptions!$C$33*(1-Assumptions!$C$39)+Assumptions!$C$26/1000000*Assumptions!$C$34)*(1+Assumptions!$C$41) -> 678.3 | J36: =Drivers!J11*(Assumptions!$C$25/1000000*Assumptions!$C$33*(1-Assumptions!$C$39)+Assumptions!$C$26/1000000*Assumptions!$C$34)*(1+Assumptions!$C$41) -> 1040.06 | ... AF36: =Drivers!AF11*(Assumptions!$C$25/1000000*Assumptions!$C$33*(1-Assumptions!$C$39)+Assumptions!$C$26/1000000*Assumptions!$C$34)*(1+Assumptions!$C$41) -> 22610
B37: Vision response (Sonnet, per drawing) | C37: =Drivers!C12*(Assumptions!$C$27/1000000*Assumptions!$C$35+Assumptions!$C$28/1000000*Assumptions!$C$36)*(1-Assumptions!$C$40)*(1+Assumptions!$C$41) -> 175.56 | D37: =Drivers!D12*(Assumptions!$C$27/1000000*Assumptions!$C$35+Assumptions!$C$28/1000000*Assumptions!$C$36)*(1-Assumptions!$C$40)*(1+Assumptions!$C$41) -> 395.01 | E37: =Drivers!E12*(Assumptions!$C$27/1000000*Assumptions!$C$35+Assumptions!$C$28/1000000*Assumptions!$C$36)*(1-Assumptions!$C$40)*(1+Assumptions!$C$41) -> 702.24 | F37: =Drivers!F12*(Assumptions!$C$27/1000000*Assumptions!$C$35+Assumptions!$C$28/1000000*Assumptions!$C$36)*(1-Assumptions!$C$40)*(1+Assumptions!$C$41) -> 1141.14 | G37: =Drivers!G12*(Assumptions!$C$27/1000000*Assumptions!$C$35+Assumptions!$C$28/1000000*Assumptions!$C$36)*(1-Assumptions!$C$40)*(1+Assumptions!$C$41) -> 1645.875 | H37: =Drivers!H12*(Assumptions!$C$27/1000000*Assumptions!$C$35+Assumptions!$C$28/1000000*Assumptions!$C$36)*(1-Assumptions!$C$40)*(1+Assumptions!$C$41) -> 2194.5 | I37: =Drivers!I12*(Assumptions!$C$27/1000000*Assumptions!$C$35+Assumptions!$C$28/1000000*Assumptions!$C$36)*(1-Assumptions!$C$40)*(1+Assumptions!$C$41) -> 3291.75 | J37: =Drivers!J12*(Assumptions!$C$27/1000000*Assumptions!$C$35+Assumptions!$C$28/1000000*Assumptions!$C$36)*(1-Assumptions!$C$40)*(1+Assumptions!$C$41) -> 5047.35 | ... AF37: =Drivers!AF12*(Assumptions!$C$27/1000000*Assumptions!$C$35+Assumptions!$C$28/1000000*Assumptions!$C$36)*(1-Assumptions!$C$40)*(1+Assumptions!$C$41) -> 109725
B38: Daily prompt generation (Opus, universal) | C38: =Assumptions!$C$29*30.4*(Assumptions!$C$30/1000000*Assumptions!$C$37+Assumptions!$C$31/1000000*Assumptions!$C$38)*(1+Assumptions!$C$41) -> 5.32 | D38: =Assumptions!$C$29*30.4*(Assumptions!$C$30/1000000*Assumptions!$C$37+Assumptions!$C$31/1000000*Assumptions!$C$38)*(1+Assumptions!$C$41) -> 5.32 | E38: =Assumptions!$C$29*30.4*(Assumptions!$C$30/1000000*Assumptions!$C$37+Assumptions!$C$31/1000000*Assumptions!$C$38)*(1+Assumptions!$C$41) -> 5.32 | F38: =Assumptions!$C$29*30.4*(Assumptions!$C$30/1000000*Assumptions!$C$37+Assumptions!$C$31/1000000*Assumptions!$C$38)*(1+Assumptions!$C$41) -> 5.32 | G38: =Assumptions!$C$29*30.4*(Assumptions!$C$30/1000000*Assumptions!$C$37+Assumptions!$C$31/1000000*Assumptions!$C$38)*(1+Assumptions!$C$41) -> 5.32 | H38: =Assumptions!$C$29*30.4*(Assumptions!$C$30/1000000*Assumptions!$C$37+Assumptions!$C$31/1000000*Assumptions!$C$38)*(1+Assumptions!$C$41) -> 5.32 | I38: =Assumptions!$C$29*30.4*(Assumptions!$C$30/1000000*Assumptions!$C$37+Assumptions!$C$31/1000000*Assumptions!$C$38)*(1+Assumptions!$C$41) -> 5.32 | J38: =Assumptions!$C$29*30.4*(Assumptions!$C$30/1000000*Assumptions!$C$37+Assumptions!$C$31/1000000*Assumptions!$C$38)*(1+Assumptions!$C$41) -> 5.32 | ... AF38: =Assumptions!$C$29*30.4*(Assumptions!$C$30/1000000*Assumptions!$C$37+Assumptions!$C$31/1000000*Assumptions!$C$38)*(1+Assumptions!$C$41) -> 5.32
B39: AI App subtotal | C39: =C36+C37+C38 -> 217.056 | D39: =D36+D37+D38 -> 481.726 | E39: =E36+E37+E38 -> 852.264 | F39: =F36+F37+F38 -> 1381.604 | G39: =G36+G37+G38 -> 1990.345 | H39: =H36+H37+H38 -> 2652.02 | I39: =I36+I37+I38 -> 3975.37 | J39: =J36+J37+J38 -> 6092.73 | ... AF39: =AF36+AF37+AF38 -> 132340.32
B40: DATA LAKE / ML RESEARCH (starts after Year 1)
B41: Lake storage (de-identified datasets) | C41: =IF((1)>=Assumptions!$C$88,Drivers!C7/1000*Assumptions!$C$89*Assumptions!$C$90,0) -> 0 | D41: =IF((2)>=Assumptions!$C$88,Drivers!D7/1000*Assumptions!$C$89*Assumptions!$C$90,0) -> 0 | E41: =IF((3)>=Assumptions!$C$88,Drivers!E7/1000*Assumptions!$C$89*Assumptions!$C$90,0) -> 0 | F41: =IF((4)>=Assumptions!$C$88,Drivers!F7/1000*Assumptions!$C$89*Assumptions!$C$90,0) -> 0 | G41: =IF((5)>=Assumptions!$C$88,Drivers!G7/1000*Assumptions!$C$89*Assumptions!$C$90,0) -> 0 | H41: =IF((6)>=Assumptions!$C$88,Drivers!H7/1000*Assumptions!$C$89*Assumptions!$C$90,0) -> 0 | I41: =IF((7)>=Assumptions!$C$88,Drivers!I7/1000*Assumptions!$C$89*Assumptions!$C$90,0) -> 0 | J41: =IF((8)>=Assumptions!$C$88,Drivers!J7/1000*Assumptions!$C$89*Assumptions!$C$90,0) -> 0 | K41: =IF((9)>=Assumptions!$C$88,Drivers!K7/1000*Assumptions!$C$89*Assumptions!$C$90,0) -> 0 | L41: =IF((10)>=Assumptions!$C$88,Drivers!L7/1000*Assumptions!$C$89*Assumptions!$C$90,0) -> 0 | M41: =IF((11)>=Assumptions!$C$88,Drivers!M7/1000*Assumptions!$C$89*Assumptions!$C$90,0) -> 0 | N41: =IF((12)>=Assumptions!$C$88,Drivers!N7/1000*Assumptions!$C$89*Assumptions!$C$90,0) -> 0 | O41: =IF((13)>=Assumptions!$C$88,Drivers!O7/1000*Assumptions!$C$89*Assumptions!$C$90,0) -> 28.8 | P41: =IF((14)>=Assumptions!$C$88,Drivers!P7/1000*Assumptions!$C$89*Assumptions!$C$90,0) -> 34.8 | Q41: =IF((15)>=Assumptions!$C$88,Drivers!Q7/1000*Assumptions!$C$89*Assumptions!$C$90,0) -> 41.28 | R41: =IF((16)>=Assumptions!$C$88,Drivers!R7/1000*Assumptions!$C$89*Assumptions!$C$90,0) -> 49.2 | S41: =IF((17)>=Assumptions!$C$88,Drivers!S7/1000*Assumptions!$C$89*Assumptions!$C$90,0) -> 60 | T41: =IF((18)>=Assumptions!$C$88,Drivers!T7/1000*Assumptions!$C$89*Assumptions!$C$90,0) -> 72 | U41: =IF((19)>=Assumptions!$C$88,Drivers!U7/1000*Assumptions!$C$89*Assumptions!$C$90,0) -> 75.6 | V41: =IF((20)>=Assumptions!$C$88,Drivers!V7/1000*Assumptions!$C$89*Assumptions!$C$90,0) -> 79.2 | W41: =IF((21)>=Assumptions!$C$88,Drivers!W7/1000*Assumptions!$C$89*Assumptions!$C$90,0) -> 82.8 | X41: =IF((22)>=Assumptions!$C$88,Drivers!X7/1000*Assumptions!$C$89*Assumptions!$C$90,0) -> 86.4 | Y41: =IF((23)>=Assumptions!$C$88,Drivers!Y7/1000*Assumptions!$C$89*Assumptions!$C$90,0) -> 90 | Z41: =IF((24)>=Assumptions!$C$88,Drivers!Z7/1000*Assumptions!$C$89*Assumptions!$C$90,0) -> 93.6 | AA41: =IF((25)>=Assumptions!$C$88,Drivers!AA7/1000*Assumptions!$C$89*Assumptions!$C$90,0) -> 98.4 | AB41: =IF((26)>=Assumptions!$C$88,Drivers!AB7/1000*Assumptions!$C$89*Assumptions!$C$90,0) -> 103.2 | AC41: =IF((27)>=Assumptions!$C$88,Drivers!AC7/1000*Assumptions!$C$89*Assumptions!$C$90,0) -> 108 | AD41: =IF((28)>=Assumptions!$C$88,Drivers!AD7/1000*Assumptions!$C$89*Assumptions!$C$90,0) -> 111.6 | AE41: =IF((29)>=Assumptions!$C$88,Drivers!AE7/1000*Assumptions!$C$89*Assumptions!$C$90,0) -> 115.68 | AF41: =IF((30)>=Assumptions!$C$88,Drivers!AF7/1000*Assumptions!$C$89*Assumptions!$C$90,0) -> 120
...
